<?xml version="1.0"?>
<robot xmlns:xacro="http://www.ros.org/wiki/xacro" name="robot">

    <xacro:include filename="inertial_macros.xacro" />

    <material name="white">
        <color rgba="1 1 1 1" />
    </material>

    <material name="orange">
        <color rgba="1 0.3 0.1 1" />
    </material>

    <material name="blue">
        <color rgba="0.2 0.2 1 1" />
    </material>

    <material name="black">
        <color rgba="0 0 0 1" />
    </material>


    <!-- BASE Link -->
    <link name="base_link">
    
    </link>

    <!-- Chassis Link -->
    <joint name="chassis_joint" type="fixed">
        <parent link="base_link"/>
        <child link="chassis"/>
        <origin xyz="0 0 0"/>
    </joint>

    <link name="chassis">
        <visual>
            <origin xyz ="0 0 0"/>
            <geometry>
                <box size="0.77 0.62 0.25" />
            </geometry>
            <material name="white"/>
        </visual>
        <collision>
            <origin xyz ="0 0 0"/>
            <geometry>
                <box size="0.77 0.62 0.25" />
            </geometry>
        </collision>
        <xacro:inertial_box mass="20" x="0.77" y="0.62" z="0.25">
            <origin xyz="0 0 0" rpy="0 0 0"/>
        </xacro:inertial_box>
    </link>

    <gazebo reference="chassis">
        <material>Gazebo/White</material>
    </gazebo>


    <!-- Front Left Wheel Link -->
    <joint name="front_left_wheel_joint" type="continuous">
        <parent link="base_link" />
        <child link="front_left_wheel" />
        <origin xyz ="0.44071 -0.44259 -0.19571" rpy="-${pi/2} 0 0" /> 
        <axis xyz="0 0 1" />
    </joint>

    <link name="front_left_wheel">
        <visual>
            <geometry>
                <cylinder radius="0.15" length="0.09" />
            </geometry>
            <material name="blue"/>
        </visual>
        <collision>
            <geometry>
                <cylinder radius="0.15" length="0.09" />
            </geometry>
        </collision>
        <xacro:inertial_cylinder mass="1.2" length="0.09" radius="0.15">
            <origin xyz="0 0 0" rpy="0 0 0"/>
        </xacro:inertial_cylinder>
    </link>
    
    <gazebo reference="front_left_wheel">
        <material>Gazebo/Blue</material>
    </gazebo>

    <!-- Front Right Wheel Link -->
    <joint name="front_right_wheel_joint" type="continuous">
        <parent link="base_link" />
        <child link="front_right_wheel" />
        <origin xyz ="0.44071 0.44259 -0.19571" rpy="${pi/2} 0 0" /> 
        <axis xyz="0 0 -1" />
    </joint>

    <link name="front_right_wheel">
        <visual>
        
            <geometry>
                <cylinder radius="0.15" length="0.09" />
            </geometry>
            <material name="blue"/>
        </visual>
        <collision>
            <geometry>
                <cylinder radius="0.15" length="0.09" />
            </geometry>
        </collision>
        <xacro:inertial_cylinder mass="1.2" length="0.09" radius="0.15">
            <origin xyz="0 0 0" rpy="0 0 0"/>
        </xacro:inertial_cylinder>
    </link>

    <gazebo reference="front_right_wheel">
        <material>Gazebo/Blue</material>
    </gazebo>

    <!-- Back Left Wheel Link -->
    <joint name="back_left_wheel_joint" type="continuous">
        <parent link="base_link" />
        <child link="back_left_wheel" />
        <origin xyz ="-0.44071 -0.44259 -0.19571" rpy="-${pi/2} 0 0" /> 
        <axis xyz="0 0 1" />
    </joint>

    <link name="back_left_wheel">
        <visual>
            <geometry>
                <cylinder radius="0.15" length="0.09" />
            </geometry>
            <material name="blue"/>
        </visual>
        <collision>
            <geometry>
                <cylinder radius="0.15" length="0.09" />
            </geometry>
        </collision>
        <xacro:inertial_cylinder mass="1.2" length="0.09" radius="0.15">
            <origin xyz="0 0 0" rpy="0 0 0"/>
        </xacro:inertial_cylinder>
    </link>

    <gazebo reference="back_left_wheel">
        <material>Gazebo/Blue</material>
    </gazebo>

    <!-- Back Right Wheel Link -->
    <joint name="back_right_wheel_joint" type="continuous">
        <parent link="base_link" />
        <child link="back_right_wheel" />
        <origin xyz ="-0.44071 0.44259 -0.19571" rpy="${pi/2} 0 0" /> 
        <axis xyz="0 0 -1" />
    </joint>

    <link name="back_right_wheel">
        <visual>
            <geometry>
                <cylinder radius="0.15" length="0.09" />
            </geometry>
            <material name="blue"/>
        </visual>
        <collision>
            <geometry>
                <cylinder radius="0.15" length="0.09" />
            </geometry>
        </collision>
        <xacro:inertial_cylinder mass="1.2" length="0.09" radius="0.15">
            <origin xyz="0 0 0" rpy="0 0 0"/>
        </xacro:inertial_cylinder>
    </link>

    <gazebo reference="back_right_wheel">
        <material>Gazebo/Blue</material>
    </gazebo>

</robot>